<?xml version="1.0" ?>
<robot name="panda_mobile_base" xmlns:xacro="http://www.ros.org/wiki/xacro">

  <!-- Mobile Base -->
  <link name="mobile_base">
    <visual>
      <geometry>
        <box size="0.6 0.6 0.2"/> <!-- Base dimensions -->
      </geometry>
      <material name="base_grey">
        <color rgba="0.5 0.5 0.5 1.0"/>
      </material>
    </visual>
    <collision>
      <geometry>
        <box size="0.6 0.6 0.2"/>
      </geometry>
    </collision>
    <inertial>
      <origin rpy="0 0 0" xyz="0 0 0"/>
      <mass value="30.0"/>
      <inertia ixx="1.0" ixy="0.0" ixz="0.0" iyy="1.0" iyz="0.0" izz="1.0"/>
    </inertial>
  </link>

  <!-- Pole Links -->
  <link name="front_left_pole">
    <visual>
      <geometry>
        <cylinder length="0.1" radius="0.02"/> <!-- Pole-like joint -->
      </geometry>
      <material name="pole_black">
        <color rgba="0.2 0.2 0.2 1.0"/>
      </material>
    </visual>
    <collision>
      <geometry>
        <cylinder length="0.1" radius="0.02"/>
      </geometry>
    </collision>
    <inertial>
      <origin rpy="0 0 0" xyz="0 0 -0.05"/>
      <mass value="0.2"/>
      <inertia ixx="0.002" ixy="0" ixz="0" iyy="0.002" iyz="0" izz="0.002"/>
    </inertial>
  </link>

  <!-- Repeat for all poles -->
  <link name="front_right_pole">
    <visual>
      <geometry>
        <cylinder length="0.1" radius="0.02"/>
      </geometry>
      <material name="pole_black"/>
    </visual>
    <collision>
      <geometry>
        <cylinder length="0.1" radius="0.02"/>
      </geometry>
    </collision>
    <inertial>
      <origin rpy="0 0 0" xyz="0 0 -0.05"/>
      <mass value="0.2"/>
      <inertia ixx="0.002" ixy="0" ixz="0" iyy="0.002" iyz="0" izz="0.002"/>
    </inertial>
  </link>

  <link name="rear_left_pole">
    <visual>
      <geometry>
        <cylinder length="0.1" radius="0.02"/>
      </geometry>
      <material name="pole_black"/>
    </visual>
    <collision>
      <geometry>
        <cylinder length="0.1" radius="0.02"/>
      </geometry>
    </collision>
    <inertial>
      <origin rpy="0 0 0" xyz="0 0 -0.05"/>
      <mass value="0.2"/>
      <inertia ixx="0.002" ixy="0" ixz="0" iyy="0.002" iyz="0" izz="0.002"/>
    </inertial>
  </link>

  <link name="rear_right_pole">
    <visual>
      <geometry>
        <cylinder length="0.1" radius="0.02"/>
      </geometry>
      <material name="pole_black"/>
    </visual>
    <collision>
      <geometry>
        <cylinder length="0.1" radius="0.02"/>
      </geometry>
    </collision>
    <inertial>
      <origin rpy="0 0 0" xyz="0 0 -0.05"/>
      <mass value="0.2"/>
      <inertia ixx="0.002" ixy="0" ixz="0" iyy="0.002" iyz="0" izz="0.002"/>
    </inertial>
  </link>

  <!-- Wheel Links -->
  <!-- Front Left Wheel -->
  <link name="front_left_wheel">
    <visual>
      <geometry>
        <cylinder length="0.05" radius="0.05"/> <!-- Wheel dimensions -->
      </geometry>
      <material name="wheel_black">
        <color rgba="0.1 0.1 0.1 1.0"/>
      </material>
    </visual>
    <collision>
      <geometry>
        <cylinder length="0.05" radius="0.05"/> <!-- Collision geometry -->
      </geometry>
    </collision>
    <inertial>
      <origin rpy="0 0 0" xyz="0 0 0"/> <!-- Center of mass at the origin -->
      <mass value="0.5"/> <!-- Mass of the wheel -->
      <inertia ixx="0.01" ixy="0" ixz="0" iyy="0.01" iyz="0" izz="0.01"/> <!-- Inertia tensor -->
    </inertial>
  </link>

  <!-- Front Right Wheel -->
  <link name="front_right_wheel">
    <visual>
      <geometry>
        <cylinder length="0.05" radius="0.05"/> <!-- Wheel dimensions -->
      </geometry>
      <material name="wheel_black">
        <color rgba="0.1 0.1 0.1 1.0"/>
      </material>
    </visual>
    <collision>
      <geometry>
        <cylinder length="0.05" radius="0.05"/> <!-- Collision geometry -->
      </geometry>
    </collision>
    <inertial>
      <origin rpy="0 0 0" xyz="0 0 0"/> <!-- Center of mass at the origin -->
      <mass value="0.5"/> <!-- Mass of the wheel -->
      <inertia ixx="0.01" ixy="0" ixz="0" iyy="0.01" iyz="0" izz="0.01"/> <!-- Inertia tensor -->
    </inertial>
  </link>

  <!-- Rear Left Wheel -->
  <link name="rear_left_wheel">
    <visual>
      <geometry>
        <cylinder length="0.05" radius="0.05"/> <!-- Wheel dimensions -->
      </geometry>
      <material name="wheel_black">
        <color rgba="0.1 0.1 0.1 1.0"/>
      </material>
    </visual>
    <collision>
      <geometry>
        <cylinder length="0.05" radius="0.05"/> <!-- Collision geometry -->
      </geometry>
    </collision>
    <inertial>
      <origin rpy="0 0 0" xyz="0 0 0"/> <!-- Center of mass at the origin -->
      <mass value="0.5"/> <!-- Mass of the wheel -->
      <inertia ixx="0.01" ixy="0" ixz="0" iyy="0.01" iyz="0" izz="0.01"/> <!-- Inertia tensor -->
    </inertial>
  </link>

  <!-- Rear Right Wheel -->
  <link name="rear_right_wheel">
    <visual>
      <geometry>
        <cylinder length="0.05" radius="0.05"/> <!-- Wheel dimensions -->
      </geometry>
      <material name="wheel_black">
        <color rgba="0.1 0.1 0.1 1.0"/>
      </material>
    </visual>
    <collision>
      <geometry>
        <cylinder length="0.05" radius="0.05"/> <!-- Collision geometry -->
      </geometry>
    </collision>
    <inertial>
      <origin rpy="0 0 0" xyz="0 0 0"/> <!-- Center of mass at the origin -->
      <mass value="0.5"/> <!-- Mass of the wheel -->
      <inertia ixx="0.01" ixy="0" ixz="0" iyy="0.01" iyz="0" izz="0.01"/> <!-- Inertia tensor -->
    </inertial>
  </link>


  <!-- Steering Joints: Pole to Base -->
  <joint name="front_left_pole_joint" type="continuous">
    <origin xyz="0.25 0.25 -0.1" rpy="0 0 0"/>
    <parent link="mobile_base"/>
    <child link="front_left_pole"/>
    <axis xyz="0 0 1"/> <!-- Rotates about Z-axis -->
  </joint>

  <joint name="front_right_pole_joint" type="continuous">
    <origin xyz="0.25 -0.25 -0.1" rpy="0 0 0"/>
    <parent link="mobile_base"/>
    <child link="front_right_pole"/>
    <axis xyz="0 0 1"/> <!-- Rotates about Z-axis -->
  </joint>

  <joint name="rear_left_pole_joint" type="continuous">
    <origin xyz="-0.25 0.25 -0.1" rpy="0 0 0"/>
    <parent link="mobile_base"/>
    <child link="rear_left_pole"/>
    <axis xyz="0 0 1"/> <!-- Rotates about Z-axis -->
  </joint>

  <joint name="rear_right_pole_joint" type="continuous">
    <origin xyz="-0.25 -0.25 -0.1" rpy="0 0 0"/>
    <parent link="mobile_base"/>
    <child link="rear_right_pole"/>
    <axis xyz="0 0 1"/> <!-- Rotates about Z-axis -->
  </joint>

  <!-- Wheel Rotation Joints -->
  <joint name="front_left_wheel_rotation_joint" type="continuous">
    <origin xyz="0 0 -0.05" rpy="0 1.5708 0"/>
    <parent link="front_left_pole"/>
    <child link="front_left_wheel"/>
    <axis xyz="0 0 1"/> <!-- Wheel rotation about its own axis -->
  </joint>

  <joint name="front_right_wheel_rotation_joint" type="continuous">
    <origin xyz="0 0 -0.05" rpy="0 1.5708 0"/>
    <parent link="front_right_pole"/>
    <child link="front_right_wheel"/>
    <axis xyz="0 0 1"/>
  </joint>

  <joint name="rear_left_wheel_rotation_joint" type="continuous">
    <origin xyz="0 0 -0.05" rpy="0 1.5708 0"/>
    <parent link="rear_left_pole"/>
    <child link="rear_left_wheel"/>
    <axis xyz="0 0 1"/>
  </joint>

  <joint name="rear_right_wheel_rotation_joint" type="continuous">
    <origin xyz="0 0 -0.05" rpy="0 1.5708 0"/>
    <parent link="rear_right_pole"/>
    <child link="rear_right_wheel"/>
    <axis xyz="0 0 1"/>
  </joint>

  <!-- Materials -->
  <material name="base_grey">
    <color rgba="0.5 0.5 0.5 1.0"/>
  </material>
  <material name="wheel_black">
    <color rgba="0.1 0.1 0.1 1.0"/>
  </material>
  <material name="panda_white">
    <color rgba="1. 1. 1. 1."/>
  </material>
  <material name="panda_gray">
    <color rgba=".8 .8 .8 1."/>
  </material>
</robot>