<?xml version="1.0" ?>
<robot name="panda_mobile_base" xmlns:xacro="http://www.ros.org/wiki/xacro">

  <!-- Mobile Base -->
  <link name="mobile_base">
    <visual>
      <geometry>
        <box size="0.6 0.6 0.2"/> <!-- Base dimensions -->
      </geometry>
      <material name="base_grey">
        <color rgba="0.5 0.5 0.5 1.0"/>
      </material>
    </visual>
    <collision>
      <geometry>
        <box size="0.6 0.6 0.2"/>
      </geometry>
    </collision>
    <inertial>
      <origin rpy="0 0 0" xyz="0 0 0"/>
      <mass value="30.0"/>
      <inertia ixx="1.0" ixy="0.0" ixz="0.0" iyy="1.0" iyz="0.0" izz="1.0"/>
    </inertial>
  </link>

  <!-- Pole Links -->
  <link name="front_left_pole">
    <visual>
      <geometry>
        <cylinder length="0.1" radius="0.02"/> <!-- Pole-like joint -->
      </geometry>
      <material name="pole_black">
        <color rgba="0.2 0.2 0.2 1.0"/>
      </material>
    </visual>
    <collision>
      <geometry>
        <cylinder length="0.1" radius="0.02"/>
      </geometry>
    </collision>
    <inertial>
      <origin rpy="0 0 0" xyz="0 0 -0.05"/>
      <mass value="0.2"/>
      <inertia ixx="0.002" ixy="0" ixz="0" iyy="0.002" iyz="0" izz="0.002"/>
    </inertial>
  </link>

  <!-- Repeat for all poles -->
  <link name="front_right_pole">
    <visual>
      <geometry>
        <cylinder length="0.1" radius="0.02"/>
      </geometry>
      <material name="pole_black"/>
    </visual>
    <collision>
      <geometry>
        <cylinder length="0.1" radius="0.02"/>
      </geometry>
    </collision>
    <inertial>
      <origin rpy="0 0 0" xyz="0 0 -0.05"/>
      <mass value="0.2"/>
      <inertia ixx="0.002" ixy="0" ixz="0" iyy="0.002" iyz="0" izz="0.002"/>
    </inertial>
  </link>

  <link name="rear_left_pole">
    <visual>
      <geometry>
        <cylinder length="0.1" radius="0.02"/>
      </geometry>
      <material name="pole_black"/>
    </visual>
    <collision>
      <geometry>
        <cylinder length="0.1" radius="0.02"/>
      </geometry>
    </collision>
    <inertial>
      <origin rpy="0 0 0" xyz="0 0 -0.05"/>
      <mass value="0.2"/>
      <inertia ixx="0.002" ixy="0" ixz="0" iyy="0.002" iyz="0" izz="0.002"/>
    </inertial>
  </link>

  <link name="rear_right_pole">
    <visual>
      <geometry>
        <cylinder length="0.1" radius="0.02"/>
      </geometry>
      <material name="pole_black"/>
    </visual>
    <collision>
      <geometry>
        <cylinder length="0.1" radius="0.02"/>
      </geometry>
    </collision>
    <inertial>
      <origin rpy="0 0 0" xyz="0 0 -0.05"/>
      <mass value="0.2"/>
      <inertia ixx="0.002" ixy="0" ixz="0" iyy="0.002" iyz="0" izz="0.002"/>
    </inertial>
  </link>

  <!-- Wheel Links -->
  <!-- Front Left Wheel -->
  <link name="front_left_wheel">
    <visual>
      <geometry>
        <cylinder length="0.05" radius="0.05"/> <!-- Wheel dimensions -->
      </geometry>
      <material name="wheel_black">
        <color rgba="0.1 0.1 0.1 1.0"/>
      </material>
    </visual>
    <collision>
      <geometry>
        <cylinder length="0.05" radius="0.05"/> <!-- Collision geometry -->
      </geometry>
    </collision>
    <inertial>
      <origin rpy="0 0 0" xyz="0 0 0"/> <!-- Center of mass at the origin -->
      <mass value="0.5"/> <!-- Mass of the wheel -->
      <inertia ixx="0.01" ixy="0" ixz="0" iyy="0.01" iyz="0" izz="0.01"/> <!-- Inertia tensor -->
    </inertial>
  </link>

  <!-- Front Right Wheel -->
  <link name="front_right_wheel">
    <visual>
      <geometry>
        <cylinder length="0.05" radius="0.05"/> <!-- Wheel dimensions -->
      </geometry>
      <material name="wheel_black">
        <color rgba="0.1 0.1 0.1 1.0"/>
      </material>
    </visual>
    <collision>
      <geometry>
        <cylinder length="0.05" radius="0.05"/> <!-- Collision geometry -->
      </geometry>
    </collision>
    <inertial>
      <origin rpy="0 0 0" xyz="0 0 0"/> <!-- Center of mass at the origin -->
      <mass value="0.5"/> <!-- Mass of the wheel -->
      <inertia ixx="0.01" ixy="0" ixz="0" iyy="0.01" iyz="0" izz="0.01"/> <!-- Inertia tensor -->
    </inertial>
  </link>

  <!-- Rear Left Wheel -->
  <link name="rear_left_wheel">
    <visual>
      <geometry>
        <cylinder length="0.05" radius="0.05"/> <!-- Wheel dimensions -->
      </geometry>
      <material name="wheel_black">
        <color rgba="0.1 0.1 0.1 1.0"/>
      </material>
    </visual>
    <collision>
      <geometry>
        <cylinder length="0.05" radius="0.05"/> <!-- Collision geometry -->
      </geometry>
    </collision>
    <inertial>
      <origin rpy="0 0 0" xyz="0 0 0"/> <!-- Center of mass at the origin -->
      <mass value="0.5"/> <!-- Mass of the wheel -->
      <inertia ixx="0.01" ixy="0" ixz="0" iyy="0.01" iyz="0" izz="0.01"/> <!-- Inertia tensor -->
    </inertial>
  </link>

  <!-- Rear Right Wheel -->
  <link name="rear_right_wheel">
    <visual>
      <geometry>
        <cylinder length="0.05" radius="0.05"/> <!-- Wheel dimensions -->
      </geometry>
      <material name="wheel_black">
        <color rgba="0.1 0.1 0.1 1.0"/>
      </material>
    </visual>
    <collision>
      <geometry>
        <cylinder length="0.05" radius="0.05"/> <!-- Collision geometry -->
      </geometry>
    </collision>
    <inertial>
      <origin rpy="0 0 0" xyz="0 0 0"/> <!-- Center of mass at the origin -->
      <mass value="0.5"/> <!-- Mass of the wheel -->
      <inertia ixx="0.01" ixy="0" ixz="0" iyy="0.01" iyz="0" izz="0.01"/> <!-- Inertia tensor -->
    </inertial>
  </link>


  <!-- Steering Joints: Pole to Base -->
  <joint name="front_left_pole_joint" type="continuous">
    <origin xyz="0.25 0.25 -0.1" rpy="0 0 0"/>
    <parent link="mobile_base"/>
    <child link="front_left_pole"/>
    <axis xyz="0 0 1"/> <!-- Rotates about Z-axis -->
  </joint>

  <joint name="front_right_pole_joint" type="continuous">
    <origin xyz="0.25 -0.25 -0.1" rpy="0 0 0"/>
    <parent link="mobile_base"/>
    <child link="front_right_pole"/>
    <axis xyz="0 0 1"/> <!-- Rotates about Z-axis -->
  </joint>

  <joint name="rear_left_pole_joint" type="continuous">
    <origin xyz="-0.25 0.25 -0.1" rpy="0 0 0"/>
    <parent link="mobile_base"/>
    <child link="rear_left_pole"/>
    <axis xyz="0 0 1"/> <!-- Rotates about Z-axis -->
  </joint>

  <joint name="rear_right_pole_joint" type="continuous">
    <origin xyz="-0.25 -0.25 -0.1" rpy="0 0 0"/>
    <parent link="mobile_base"/>
    <child link="rear_right_pole"/>
    <axis xyz="0 0 1"/> <!-- Rotates about Z-axis -->
  </joint>

  <!-- Wheel Rotation Joints -->
  <joint name="front_left_wheel_rotation_joint" type="continuous">
    <origin xyz="0 0 -0.05" rpy="0 1.5708 0"/>
    <parent link="front_left_pole"/>
    <child link="front_left_wheel"/>
    <axis xyz="0 0 1"/> <!-- Wheel rotation about its own axis -->
  </joint>

  <joint name="front_right_wheel_rotation_joint" type="continuous">
    <origin xyz="0 0 -0.05" rpy="0 1.5708 0"/>
    <parent link="front_right_pole"/>
    <child link="front_right_wheel"/>
    <axis xyz="0 0 1"/>
  </joint>

  <joint name="rear_left_wheel_rotation_joint" type="continuous">
    <origin xyz="0 0 -0.05" rpy="0 1.5708 0"/>
    <parent link="rear_left_pole"/>
    <child link="rear_left_wheel"/>
    <axis xyz="0 0 1"/>
  </joint>

  <joint name="rear_right_wheel_rotation_joint" type="continuous">
    <origin xyz="0 0 -0.05" rpy="0 1.5708 0"/>
    <parent link="rear_right_pole"/>
    <child link="rear_right_wheel"/>
    <axis xyz="0 0 1"/>
  </joint>

  <!-- Fixed Joint: Arm Base to Mobile Base -->
  <joint name="arm_mount_joint" type="fixed">
    <origin xyz="0 0 0.1" rpy="0 0 0"/> <!-- Mount arm on top of mobile base -->
    <parent link="mobile_base"/>
    <child link="iiwa_link_0"/>
  </joint>

  <!-- IIWA Arm Links -->
  <link name="iiwa_link_0">
    <visual>
      <geometry>
        <mesh filename="package://iiwa_description/meshes/iiwa7/visual/link_0.stl"/>
      </geometry>
      <material name="panda_gray"/>
    </visual>
    <collision>
      <geometry>
        <mesh filename="package://iiwa_description/meshes/iiwa7/collision/link_0.stl"/>
      </geometry>
    </collision>
    <inertial>
      <origin xyz="0 0 0" rpy="0 0 0"/>
      <mass value="5.0"/>
      <inertia ixx="0.05" ixy="0" ixz="0" iyy="0.05" iyz="0" izz="0.05"/>
    </inertial>
  </link>

  <link name="iiwa_link_1">
    <visual>
      <geometry>
        <mesh filename="package://iiwa_description/meshes/iiwa7/visual/link_1.stl"/>
      </geometry>
      <material name="iiwa_orange">
        <color rgba="1.0 0.423529 0.0392157 1.0"/>
      </material>
    </visual>
    <collision>
      <geometry>
        <mesh filename="package://iiwa_description/meshes/iiwa7/collision/link_1.stl"/>
      </geometry>
    </collision>
    <inertial>
      <origin xyz="0 -0.03 0.12" rpy="0 0 0"/>
      <mass value="3.4525"/>
      <inertia ixx="0.0218946" ixy="0" ixz="0" iyy="0.02183" iyz="0" izz="0.00663837"/>
    </inertial>
  </link>

  <link name="iiwa_link_2">
    <visual>
      <geometry>
        <mesh filename="package://iiwa_description/meshes/iiwa7/visual/link_2.stl"/>
      </geometry>
      <material name="iiwa_orange"/>
    </visual>
    <collision>
      <geometry>
        <mesh filename="package://iiwa_description/meshes/iiwa7/collision/link_2.stl"/>
      </geometry>
    </collision>
    <inertial>
      <origin xyz="0.0003 0.059 0.042" rpy="0 0 0"/>
      <mass value="3.4821"/>
      <inertia ixx="0.02179" ixy="0" ixz="0" iyy="0.0217049" iyz="0" izz="0.00684512"/>
    </inertial>
  </link>

  <link name="iiwa_link_3">
    <visual>
      <geometry>
        <mesh filename="package://iiwa_description/meshes/iiwa7/visual/link_3.stl"/>
      </geometry>
      <material name="iiwa_orange"/>
    </visual>
    <collision>
      <geometry>
        <mesh filename="package://iiwa_description/meshes/iiwa7/collision/link_3.stl"/>
      </geometry>
    </collision>
    <inertial>
      <origin xyz="0 0.03 0.13" rpy="0 0 0"/>
      <mass value="4.05623"/>
      <inertia ixx="0.0321488" ixy="0" ixz="0" iyy="0.03204" iyz="0" izz="0.00799117"/>
    </inertial>
  </link>

  <link name="iiwa_link_4">
    <visual>
      <geometry>
        <mesh filename="package://iiwa_description/meshes/iiwa7/visual/link_4.stl"/>
      </geometry>
      <material name="iiwa_orange"/>
    </visual>
    <collision>
      <geometry>
        <mesh filename="package://iiwa_description/meshes/iiwa7/collision/link_4.stl"/>
      </geometry>
    </collision>
    <inertial>
      <origin xyz="0 0.067 0.034" rpy="0 0 0"/>
      <mass value="3.4822"/>
      <inertia ixx="0.02178" ixy="0" ixz="0" iyy="0.0216947" iyz="0" izz="0.00684029"/>
    </inertial>
  </link>

  <link name="iiwa_link_5">
    <visual>
      <geometry>
        <mesh filename="package://iiwa_description/meshes/iiwa7/visual/link_5.stl"/>
      </geometry>
      <material name="iiwa_orange"/>
    </visual>
    <collision>
      <geometry>
        <mesh filename="package://iiwa_description/meshes/iiwa7/collision/link_5.stl"/>
      </geometry>
    </collision>
    <inertial>
      <origin xyz="0.0001 0.021 0.076" rpy="0 0 0"/>
      <mass value="2.1633"/>
      <inertia ixx="0.0131987" ixy="0" ixz="0" iyy="0.01287" iyz="0" izz="0.0036293"/>
    </inertial>
  </link>

  <link name="iiwa_link_6">
    <visual>
      <geometry>
        <mesh filename="package://iiwa_description/meshes/iiwa7/visual/link_6.stl"/>
      </geometry>
      <material name="iiwa_orange"/>
    </visual>
    <collision>
      <geometry>
        <mesh filename="package://iiwa_description/meshes/iiwa7/collision/link_6.stl"/>
      </geometry>
    </collision>
    <inertial>
      <origin xyz="0 0.0006 0.0004" rpy="0 0 0"/>
      <mass value="2.3466"/>
      <inertia ixx="0.006509" ixy="0" ixz="0" iyy="0.00631585" iyz="0" izz="0.00447015"/>
    </inertial>
  </link>

  <link name="iiwa_link_7">
    <visual>
      <geometry>
        <mesh filename="package://iiwa_description/meshes/iiwa7/visual/link_7.stl"/>
      </geometry>
      <material name="panda_gray"/>
    </visual>
    <collision>
      <geometry>
        <mesh filename="package://iiwa_description/meshes/iiwa7/collision/link_7.stl"/>
      </geometry>
    </collision>
    <inertial>
      <origin xyz="0 0 0.02" rpy="0 0 0"/>
      <mass value="3.129"/>
      <inertia ixx="0.0152362" ixy="0" ixz="0" iyy="0.0140538" iyz="0" izz="0.002872"/>
    </inertial>
  </link>

  <!-- IIWA Arm Joints -->
  <joint name="iiwa_joint_1" type="revolute">
    <origin xyz="0 0 0.15" rpy="0 0 0"/>
    <parent link="iiwa_link_0"/>
    <child link="iiwa_link_1"/>
    <axis xyz="0 0 1"/>
    <limit lower="-2.96706" upper="2.96706" effort="300" velocity="1.4835"/>
    <dynamics damping="0.5"/>
  </joint>

  <joint name="iiwa_joint_2" type="revolute">
    <origin xyz="0 0 0.19" rpy="1.5708 0 3.14159"/>
    <parent link="iiwa_link_1"/>
    <child link="iiwa_link_2"/>
    <axis xyz="0 0 1"/>
    <limit lower="-2.0944" upper="2.0944" effort="300" velocity="1.4835"/>
    <dynamics damping="0.5"/>
  </joint>

  <joint name="iiwa_joint_3" type="revolute">
    <origin xyz="0 0.21 0" rpy="1.5708 0 3.14159"/>
    <parent link="iiwa_link_2"/>
    <child link="iiwa_link_3"/>
    <axis xyz="0 0 1"/>
    <limit lower="-2.96706" upper="2.96706" effort="300" velocity="1.7453"/>
    <dynamics damping="0.5"/>
  </joint>

  <joint name="iiwa_joint_4" type="revolute">
    <origin xyz="0 0 0.19" rpy="1.5708 0 0"/>
    <parent link="iiwa_link_3"/>
    <child link="iiwa_link_4"/>
    <axis xyz="0 0 1"/>
    <limit lower="-2.0944" upper="2.0944" effort="300" velocity="1.3090"/>
    <dynamics damping="0.5"/>
  </joint>

  <joint name="iiwa_joint_5" type="revolute">
    <origin xyz="0 0.21 0" rpy="-1.5708 3.14159 0"/>
    <parent link="iiwa_link_4"/>
    <child link="iiwa_link_5"/>
    <axis xyz="0 0 1"/>
    <limit lower="-2.96706" upper="2.96706" effort="300" velocity="2.2689"/>
    <dynamics damping="0.5"/>
  </joint>

  <joint name="iiwa_joint_6" type="revolute">
    <origin xyz="0 0.0607 0.19" rpy="1.5708 0 0"/>
    <parent link="iiwa_link_5"/>
    <child link="iiwa_link_6"/>
    <axis xyz="0 0 1"/>
    <limit lower="-2.0944" upper="2.0944" effort="300" velocity="2.3562"/>
    <dynamics damping="0.5"/>
  </joint>

  <joint name="iiwa_joint_7" type="revolute">
    <origin xyz="0 0.081 0.0607" rpy="-1.5708 3.14159 0"/>
    <parent link="iiwa_link_6"/>
    <child link="iiwa_link_7"/>
    <axis xyz="0 0 1"/>
    <limit lower="-3.05433" upper="3.05433" effort="300" velocity="2.3562"/>
    <dynamics damping="0.5"/>
  </joint>

  <!-- Materials -->
  <material name="base_grey">
    <color rgba="0.5 0.5 0.5 1.0"/>
  </material>
  <material name="wheel_black">
    <color rgba="0.1 0.1 0.1 1.0"/>
  </material>
  <material name="panda_white">
    <color rgba="1. 1. 1. 1."/>
  </material>
  <material name="panda_gray">
    <color rgba=".8 .8 .8 1."/>
  </material>
  <material name="iiwa_orange">
    <color rgba="1.0 0.423529 0.0392157 1.0"/>
  </material>
</robot>