<?xml version="1.0"?>
<robot name="tidybot_iiwa7">

  <link name="base_link">
    <inertial>
      <origin xyz="0 0 0" rpy="0 0 0"/>
      <mass value="60.0"/>
      <inertia
        ixx="5.0" ixy="0.0" ixz="0.0"
        iyy="5.0" iyz="0.0"
        izz="5.0"/>
    </inertial>
    <visual>
      <origin xyz="0 0 0" rpy="0 0 0"/>
      <geometry>
        <mesh filename="meshes/base/tidybot_base.stl"
              scale="0.001 0.001 0.001"/>
      </geometry>
      <material name="base_grey"/>
    </visual>
    <collision>
      <origin xyz="0 0 0" rpy="0 0 0"/>
      <geometry>
        <mesh filename="meshes/base/tidybot_base.stl"
              scale="0.001 0.001 0.001"/>
      </geometry>
    </collision>
  </link>

  <joint name="arm_mount_joint" type="fixed">
    <origin xyz="0.218 0.264 0.697275" rpy="0 0 0"/>
    <parent link="base_link"/>
    <child link="iiwa_link_0"/>
  </joint>

  <link name="iiwa_link_0">
    <visual>
      <geometry>
        <mesh filename="meshes/iiwa7/visual/link_0.stl"/>
      </geometry>
      <material name="panda_gray"/>
    </visual>
    <collision>
      <geometry>
        <mesh filename="meshes/iiwa7/collision/link_0.stl"/>
      </geometry>
    </collision>
    <inertial>
      <origin xyz="-0.10 0 0.07" rpy="0 0 0"/>
      <mass value="5.0"/>
      <inertia ixx="0.05" ixy="0" ixz="0" iyy="0.05" iyz="0" izz="0.05"/>
    </inertial>
  </link>

  <link name="iiwa_link_1">
    <visual>
      <origin xyz="0 0 0.0075" rpy="0 0 0"/>
      <geometry>
        <mesh filename="meshes/iiwa7/visual/link_1.stl"/>
      </geometry>
      <material name="iiwa_orange"/>
    </visual>
    <collision>
      <origin xyz="0 0 0.0075" rpy="0 0 0"/>
      <geometry>
        <mesh filename="meshes/iiwa7/collision/link_1.stl"/>
      </geometry>
    </collision>
    <inertial>
      <origin xyz="0 -0.03 0.12" rpy="0 0 0"/>
      <mass value="3.4525"/>
      <inertia ixx="0.02183"  ixy="0"  ixz="0" iyy="0.007703" iyz="-0.003887" izz="0.02083" />
    </inertial>
  </link>

  <joint name="iiwa_joint_1" type="revolute">
    <origin xyz="0 0 0.15" rpy="0 0 0"/>
    <parent link="iiwa_link_0"/>
    <child link="iiwa_link_1"/>
    <axis xyz="0 0 1"/>
    <limit lower="-2.96706" upper="2.96706" effort="300" velocity="1.4835"/>
    <dynamics damping="0.5"/>
  </joint>

  <link name="iiwa_link_2">
    <visual>
      <geometry>
        <mesh filename="meshes/iiwa7/visual/link_2.stl"/>
      </geometry>
      <material name="iiwa_orange"/>
    </visual>
    <collision>
      <geometry>
        <mesh filename="meshes/iiwa7/collision/link_2.stl"/>
      </geometry>
    </collision>
    <inertial>
      <origin xyz="0.0003 0.059 0.042" rpy="0 0 0"/>
      <mass value="3.4821"/>
      <inertia ixx="0.02076"  ixy="0"  ixz="-0.003626" iyy="0.02179" iyz="0" izz="0.00779" />
    </inertial>
  </link>

  <joint name="iiwa_joint_2" type="revolute">
    <origin xyz="0 0 0.19" rpy="1.5708 0 3.14159"/>
    <parent link="iiwa_link_1"/>
    <child link="iiwa_link_2"/>
    <axis xyz="0 0 1"/>
    <limit lower="-2.0944" upper="2.0944" effort="300" velocity="1.4835"/>
    <dynamics damping="0.5"/>
  </joint>

  <link name="iiwa_link_3">
    <visual>
      <origin xyz="0 0 -0.026" rpy="0 0 0"/>
      <geometry>
        <mesh filename="meshes/iiwa7/visual/link_3.stl"/>
      </geometry>
      <material name="iiwa_orange"/>
    </visual>
    <collision>
      <origin xyz="0 0 -0.026" rpy="0 0 0"/>
      <geometry>
        <mesh filename="meshes/iiwa7/collision/link_3.stl"/>
      </geometry>
    </collision>
    <inertial>
      <origin xyz="0 0.03 0.13" rpy="0 0 0"/>
      <mass value="4.05623"/>
      <inertia ixx="0.03204"  ixy="0"  ixz="0" iyy="0.00972" iyz="0.006227" izz="0.03042" />
    </inertial>
  </link>

  <joint name="iiwa_joint_3" type="revolute">
    <origin xyz="0 0.21 0" rpy="1.5708 0 3.14159"/>
    <parent link="iiwa_link_2"/>
    <child link="iiwa_link_3"/>
    <axis xyz="0 0 1"/>
    <limit lower="-2.96706" upper="2.96706" effort="300" velocity="1.7453"/>
    <dynamics damping="0.5"/>
  </joint>

  <link name="iiwa_link_4">
    <visual>
      <geometry>
        <mesh filename="meshes/iiwa7/visual/link_4.stl"/>
      </geometry>
      <material name="iiwa_orange"/>
    </visual>
    <collision>
      <geometry>
        <mesh filename="meshes/iiwa7/collision/link_4.stl"/>
      </geometry>
    </collision>
    <inertial>
      <origin xyz="0 0.067 0.034" rpy="0 0 0"/>
      <mass value="3.4822"/>
      <inertia ixx="0.02178"  ixy="0"  ixz="0" iyy="0.02075" iyz="-0.003625" izz="0.007785" />
    </inertial>
  </link>

  <joint name="iiwa_joint_4" type="revolute">
    <origin xyz="0 0 0.19" rpy="1.5708 0 0"/>
    <parent link="iiwa_link_3"/>
    <child link="iiwa_link_4"/>
    <axis xyz="0 0 1"/>
    <limit lower="-2.0944" upper="2.0944" effort="300" velocity="1.3090"/>
    <dynamics damping="0.5"/>
  </joint>

  <link name="iiwa_link_5">
    <visual>
      <origin xyz="0 0 -0.026" rpy="0 0 0"/>
      <geometry>
        <mesh filename="meshes/iiwa7/visual/link_5.stl"/>
      </geometry>
      <material name="iiwa_orange"/>
    </visual>
    <collision>
      <origin xyz="0 0 -0.026" rpy="0 0 0"/>
      <geometry>
        <mesh filename="meshes/iiwa7/collision/link_5.stl"/>
      </geometry>
    </collision>
    <inertial>
      <origin xyz="0.0001 0.021 0.076" rpy="0 0 0"/>
      <mass value="2.1633"/>
      <inertia ixx="0.01287"  ixy="0"  ixz="0" iyy="0.005708" iyz="-0.003946" izz="0.01112" />
    </inertial>
  </link>

  <joint name="iiwa_joint_5" type="revolute">
    <origin xyz="0 0.21 0" rpy="-1.5708 3.14159 0"/>
    <parent link="iiwa_link_4"/>
    <child link="iiwa_link_5"/>
    <axis xyz="0 0 1"/>
    <limit lower="-2.96706" upper="2.96706" effort="300" velocity="2.2689"/>
    <dynamics damping="0.5"/>
  </joint>

  <link name="iiwa_link_6">
    <visual>
      <geometry>
        <mesh filename="meshes/iiwa7/visual/link_6.stl"/>
      </geometry>
      <material name="iiwa_orange"/>
    </visual>
    <collision>
      <geometry>
        <mesh filename="meshes/iiwa7/collision/link_6.stl"/>
      </geometry>
    </collision>
    <inertial>
      <origin xyz="0 0.0006 0.0004" rpy="0 0 0"/>
      <mass value="2.3466"/>
      <inertia ixx="0.006509"  ixy="0"  ixz="0" iyy="0.006259" iyz="0.00031891" izz="0.004527" />
    </inertial>
  </link>

  <joint name="iiwa_joint_6" type="revolute">
    <origin xyz="0 0.0607 0.19" rpy="1.5708 0 0"/>
    <parent link="iiwa_link_5"/>
    <child link="iiwa_link_6"/>
    <axis xyz="0 0 1"/>
    <limit lower="-2.0944" upper="2.0944" effort="300" velocity="2.3562"/>
    <dynamics damping="0.5"/>
  </joint>

  <link name="iiwa_link_7">
    <visual>
      <origin xyz="0 0 -0.0005" rpy="0 0 0"/>
      <geometry>
        <mesh filename="meshes/iiwa7/visual/link_7.stl"/>
      </geometry>
      <material name="panda_gray"/>
    </visual>
    <collision>
      <origin xyz="0 0 -0.0005" rpy="0 0 0"/>
      <geometry>
        <mesh filename="meshes/iiwa7/collision/link_7.stl"/>
      </geometry>
    </collision>
    <inertial>
      <origin xyz="0 0 0.02" rpy="0 0 0"/>
      <mass value="3.129"/>
      <inertia ixx="0.01464"  ixy="0.0005912"  ixz="0" iyy="0.01465" iyz="0" izz="0.002872" />
    </inertial>
  </link>

  <joint name="iiwa_joint_7" type="revolute">
    <origin xyz="0 0.081 0.0607" rpy="-1.5708 3.14159 0"/>
    <parent link="iiwa_link_6"/>
    <child link="iiwa_link_7"/>
    <axis xyz="0 0 1"/>
    <limit lower="-3.05433" upper="3.05433" effort="300" velocity="2.3562"/>
    <dynamics damping="0.5"/>
  </joint>

  <material name="base_grey">
    <color rgba="0.5 0.5 0.5 1.0"/>
  </material>
  
  <material name="panda_white">
    <color rgba="1. 1. 1. 1."/>
  </material>

  <material name="panda_gray">
    <color rgba=".8 .8 .8 1."/>
  </material>

  <material name="iiwa_orange">
    <color rgba="1.0 0.423529 0.0392157 1.0"/>
  </material>

</robot>